## Q12 오류와 예외 처리
다음 코드의 실행 결과를 예측하고 그 이유에 대해 설명하시오.  
```
result = 0

try:
    [1, 2, 3][3]
    "a"+1
    4 / 0
except TypeError:
    result += 1
except ZeroDivisionError:
    result += 2
except IndexError:
    result += 3
finally:
    result += 4

print(result)
```

1. result의 초기값은 0이다.
2. try문 안의 `[123][3]` 이라는 문장 수행시 `IndexError`가 발생.  
   `except IndexError:` 구문으로 이동, result에 3이 더해져 3이된다.
3. 최종적으로 finally 구문이 실행되어 reault에 4가 더해져 7이 된다.
4. `print( result )`가 수행되어 result의 최종 값인 7이 출력된다.